<?xml version="1.0"?>
<robot name="optimus">

    <!-- - - -  -->
    <!-- Colors -->
    <!-- - - -  -->
    <material name="blue">
        <color rgba="0 0 0.7 1" />
    </material>
    <material name="black">
        <color rgba="0.035 0.1 0.1 1" />
    </material>

    <!-- - - - - -->
    <!-- Base -->
    <!-- - - - - -->
    <link name="base_link">
        <origin xyz="0 0 0" rpy="0 0 0" />
    </link>
    
    <!-- - - - - -->
    <!-- Chassis -->
    <!-- - - - - -->
    <link name="chassis_link">
        <visual>
            <geometry>
                <box size=".3 .18 .11" />
            </geometry>
            <origin xyz="0 0 0.055" rpy="0 0 0" />
            <material name="blue" />
        </visual>
        <collision>
            <geometry>
                <box size=".3 .18 .11" />
            </geometry>
            <origin xyz="0 0 0.055" rpy="0 0 0"/>
        </collision>
    </link>
    <joint name="foot_base_joint" type="fixed">
        <parent link="base_link" />
        <child link="chassis_link"/>
        <origin xyz="0 0 0.059" rpy="0 0 0" />
    </joint>

    <!-- - - - - -  -->
    <!-- Left Wheel -->
    <!-- - - - - -  -->
    <link name="left_wheel_link">
        <visual>
            <geometry>
                <cylinder radius="0.06" length="0.04" />
            </geometry>
            <origin xyz="0 0 0" rpy="1.55 0 0" />
            <material name="black" />
        </visual>
    </link>
    <joint name="base_left_wheel_joint" type="continuous">
        <parent link="chassis_link" />
        <child link="left_wheel_link"/>
        <origin xyz="-0.07 -0.11 0" rpy="0 0 0" />
        <axis xyz="0 1 0" />
    </joint>
    
    <!-- - - - - - - -->
    <!-- Right Wheel -->
    <!-- - - - - - - -->
    <link name="right_wheel_link">
        <visual>
            <geometry>
                <cylinder radius="0.06" length="0.04" />
            </geometry>
            <origin xyz="0 0 0" rpy="-1.55 0 0" />
            <material name="black" />
        </visual>
    </link>
    <joint name="base_right_wheel_joint" type="continuous">
        <parent link="chassis_link" />
        <child link="right_wheel_link"/>
        <origin xyz="-0.07 0.11 0" rpy="0 0 0" />
        <axis xyz="0 1 0" />
    </joint>


    <!-- - - - - -  -->
    <!-- - Caster - -->
    <!-- - - - - -  -->
    <link name="caster_wheel_link">
        <visual>
            <geometry>
                <sphere radius="0.03" />
            </geometry>
            <origin xyz="0 0 0" rpy="0 0 0" />
            <material name="black" />
        </visual>
    </link>
    <joint name="base_caster_wheel_joint" type="fixed">
        <parent link="chassis_link" />
        <child link="caster_wheel_link"/>
        <origin xyz=".1 0 -.029" rpy="0 0 0" />
    </joint>
</robot>